Workbook

Sheet Indice
A1: ANEXO TECNICO DE DATOS - CURUBA (Passiflora mollissima Bailey)
A2: Universidad EAN | Inteligencia en Negocios Globales | Grupo 5, Equipo 6 | Acompana la Ficha Tecnica del Estudio
A4: Hoja | B4: Contenido | C4: Capa de datos | D4: Fuente
A5: TradeMap_Datos | B5: Exportaciones de la subpartida 081090 por economia, 2016-2025 (USD miles) | C5: Primaria | D5: Trade Map (ITC)
A6: Participacion | B6: Cuota de cada economia en las exportaciones mundiales, por ano | C6: Primaria - calculada | D6: Calculo sobre Trade Map
A7: HHI_Oferta | B7: Concentracion de la oferta mundial: HHI, escala 0-10.000 y numero equivalente | C7: Primaria - calculada | D7: Calculo sobre Trade Map
A8: Andinos | B8: Colombia frente a Ecuador y Peru: valor, cuota, razon y crecimiento | C8: Primaria - calculada | D8: Calculo sobre Trade Map
A9: Cobertura | B9: Economias que reportan cada ano y aptitud del ano para ranking | C9: Primaria - calculada | D9: Calculo sobre Trade Map
A10: Conjunto_A | B10: Comercio mundial de pasifloras por region, 2019-2024 | C10: Estimacion del equipo | D10: Ficha tecnica, seccion 3.1
A11: Conjunto_B | B11: Variables macroeconomicas de Colombia, 2019-2024 | C11: Estimacion del equipo | D11: Ficha tecnica, seccion 3.1
A12: Conjunto_C | B12: Produccion de pasifloras y curuba, e imputacion del 3,8 % | C12: Estimacion del equipo | D12: Ficha tecnica, seccion 3.1
A13: Posicion_Comercial | B13: IBCR, IAC y clasificacion de los seis mercados | C13: Estimacion del equipo | D13: Ficha tecnica, seccion 3.2
A14: Concentracion | B14: HHI, Theil y Grubel-Lloyd: curuba frente a gulupa | C14: Estimacion del equipo | D14: Ficha tecnica, seccion 3.3
A15: Ventaja_Comparativa | B15: Balassa, RSCA y Lafay | C15: Estimacion del equipo | D15: Ficha tecnica, seccion 3.4
... A18: Diccionario | B18: Definicion, unidad y fuente de cada campo del anexo | C18: Documentacion | D18: Elaboracion propia
A21: LEYENDA
A22: Celda con fondo gris claro = dato de entrada (proviene de la fuente o de la ficha tecnica).
A23: Celda sin fondo = valor calculado por formula; se recalcula solo al cambiar las entradas.
A24: Los valores monetarios estan en miles de dolares corrientes (USD miles), como los entrega Trade Map.
A25: Capa 'Primaria' = descarga oficial de Trade Map. Capa 'Estimacion del equipo' = cifras de la ficha tecnica construidas sobre el supuesto de imputacion del 3,8 % (ver hoja Supuestos).

Sheet TradeMap_Datos
A1: Exportaciones de la subpartida 081090 por economia
A2: Trade Map (ITC). Valores en USD miles. Fila 5 = agregado Mundo del archivo original; las economias empiezan en la fila 6.
A4: Codigo | B4: Economia | C4: 2016 | D4: 2017 | E4: 2018 | F4: 2019 | G4: 2020 | H4: 2021 | I4: 2022 | J4: 2023 | K4: 2024 | L4: 2025
A5: 000 | B5: Mundo (agregado) | C5: 3079157 | D5: 3832377 | E5: 3955960 | F5: 4441897 | G5: 4000859 | H5: 4465542 | I5: 3531990 | J5: 3680125 | K5: 3904393 | L5: 3209449
A6: 764 | B6: Tailandia | C6: 415410 | D6: 709184 | E6: 640477 | F6: 785921 | G6: 630149 | H6: 838617 | I6: 604264 | J6: 572381 | K6: 654781 | L6: 656331
A7: 528 | B7: Países Bajos | C7: 219321 | D7: 236407 | E7: 286543 | F7: 293639 | G7: 338683 | H7: 329102 | I7: 293367 | J7: 319501 | K7: 330538 | L7: 391278
A8: 218 | B8: Ecuador | C8: 10228 | D8: 16345 | E8: 38202 | F8: 69241 | G8: 92677 | H8: 99707 | I8: 121742 | J8: 186888 | K8: 233457 | L8: 341984
A9: 156 | B9: China | C9: 167986 | D9: 126473 | E9: 160001 | F9: 244836 | G9: 250775 | H9: 251668 | I9: 202245 | J9: 220894 | K9: 252459 | L9: 251468
A10: 792 | B10: Türkiye | C10: 104253 | D10: 97302 | E10: 115029 | F10: 98166 | G10: 126075 | H10: 134518 | I10: 119186 | J10: 136615 | K10: 163954 | L10: 168183
A11: 818 | B11: Egipto | C11: 127819 | D11: 97836 | E11: 76887 | F11: 73090 | G11: 67571 | H11: 71915 | I11: 131793 | J11: 146553 | K11: 171520 | L11: 167976
A12: 724 | B12: España | C12: 89324 | D12: 118685 | E12: 91875 | F12: 96146 | G12: 87874 | H12: 100576 | I12: 87613 | J12: 93897 | K12: 117239 | L12: 141318
A13: 604 | B13: Perú | C13: 41180 | D13: 59914 | E13: 71178 | F13: 68209 | G13: 63788 | H13: 83514 | I13: 83381 | J13: 88774 | K13: 88624 | L13: 121763
A14: 699 | B14: India | C14: 81263 | D14: 109477 | E14: 98482 | F14: 114529 | G14: 89878 | H14: 95807 | I14: 78086 | J14: 79090 | K14: 94792 | L14: 119164
A15: 170 | B15: Colombia | C15: 57044 | D15: 62041 | E15: 74863 | F15: 80197 | G15: 76931 | H15: 94058 | I15: 98775 | J15: 98897 | K15: 106407 | L15: 116451
A16: 842 | B16: Estados Unidos de América | C16: 62342 | D16: 63730 | E16: 68048 | F16: 69765 | G16: 77878 | H16: 73101 | I16: 61150 | J16: 62302 | K16: 73698 | L16: 75124
... A29: 344 | B29: Hong Kong, China | C29: 89457 | D29: 123789 | E29: 82966 | F29: 121181 | G29: 105764 | H29: 233954 | I29: 87274 | J29: 18714 | K29: 20778 | L29: 17140
A30: 144 | B30: Sri Lanka | C30: 6102 | D30: 8245 | F30: 10940 | G30: 6377 | H30: 10172 | I30: 11281 | J30: 10921 | K30: 11259 | L30: 14986
A31: 360 | B31: Indonesia | C31: 6739 | D31: 3354 | E31: 3010 | F31: 3798 | G31: 2638 | H31: 2860 | I31: 4678 | J31: 5914 | K31: 8007 | L31: 14305
A32: 320 | B32: Guatemala | C32: 7033 | D32: 7261 | E32: 9828 | F32: 8175 | G32: 10554 | H32: 12340 | I32: 14237 | J32: 13377 | K32: 12027 | L32: 13550
A33: 620 | B33: Portugal | C33: 2876 | D33: 7897 | E33: 4836 | F33: 3336 | G33: 2513 | H33: 2024 | I33: 2712 | J33: 7191 | K33: 8292 | L33: 12875
A34: 490 | B34: Taipei Chino | C34: 36355 | D34: 33955 | E34: 48563 | F34: 63374 | G34: 69839 | H34: 68344 | I34: 13525 | J34: 10353 | K34: 25058 | L34: 11802
A35: 100 | B35: Bulgaria | C35: 562 | D35: 523 | E35: 859 | F35: 338 | G35: 519 | H35: 2016 | I35: 3013 | J35: 4668 | K35: 5366 | L35: 8932
A36: 682 | B36: Arabia Saudita | C36: 10252 | D36: 14865 | E36: 17225 | F36: 10579 | G36: 14676 | H36: 7819 | I36: 16311 | J36: 10123 | K36: 3932 | L36: 8109
A37: 348 | B37: Hungría | C37: 4789 | D37: 8586 | E37: 3484 | F37: 5965 | G37: 14352 | H37: 21907 | I37: 10405 | J37: 5001 | K37: 10055 | L37: 7867
A38: 076 | B38: Brasil | C38: 1763 | D38: 1582 | E38: 2425 | F38: 2990 | G38: 2048 | H38: 4068 | I38: 5859 | J38: 5801 | K38: 5097 | L38: 7394
A39: 504 | B39: Marruecos | C39: 6223 | D39: 10751 | E39: 8574 | F39: 8277 | G39: 5375 | H39: 6056 | I39: 3938 | J39: 5528 | K39: 4051 | L39: 7217
A40: 036 | B40: Australia | C40: 2151 | D40: 5134 | E40: 3806 | F40: 2996 | G40: 4774 | H40: 6367 | I40: 9951 | J40: 7058 | K40: 7730 | L40: 4857
A41: 554 | B41: Nueva Zelandia | C41: 4480 | D41: 4559 | E41: 4442 | F41: 2752 | G41: 3409 | H41: 3706 | I41: 2942 | J41: 2852 | K41: 3140 | L41: 4141
A42: 480 | B42: Mauricio | C42: 1576 | D42: 937 | E42: 2110 | F42: 1284 | G42: 1361 | H42: 1574 | I42: 1896 | J42: 1981 | K42: 2494 | L42: 4131
... A114: 032 | B114: Argentina | C114: 856 | D114: 1359 | E114: 0 | F114: 2967 | G114: 2221 | H114: 42 | I114: 0 | J114: 0 | K114: 0 | L114: 0
A115: 860 | B115: Uzbekistán | D115: 7732 | E115: 9724 | F115: 34300 | G115: 18600 | H115: 14985 | I115: 19813 | J115: 13812 | K115: 4973
A116: 887 | B116: Yemen | J116: 15094 | K116: 24647
A117: 776 | B117: Tonga | D117: 0 | E117: 0 | F117: 4 | G117: 5 | H117: 39 | I117: 26 | J117: 20 | K117: 61
A118: 784 | B118: Emiratos Árabes Unidos | C118: 24181 | D118: 23954 | E118: 62204 | F118: 75205 | G118: 52680 | H118: 96306 | I118: 108007 | J118: 101656 | K118: 95092
A119: 788 | B119: Túnez | C119: 3095 | D119: 4342 | E119: 8694 | F119: 8547 | G119: 5578 | H119: 11234 | I119: 13387 | J119: 11186 | K119: 10326
A120: 804 | B120: Ucrania | C120: 7 | D120: 126 | E120: 123 | F120: 224 | G120: 391 | H120: 831 | I120: 133 | J120: 171 | K120: 100
A121: 807 | B121: Macedonia del Norte | C121: 26 | D121: 6 | E121: 10 | F121: 19 | G121: 29 | H121: 17 | I121: 7 | J121: 52 | K121: 109
A122: 566 | B122: Nigeria | C122: 0 | D122: 0 | E122: 2152 | F122: 0 | G122: 0 | H122: 0 | I122: 0 | J122: 27 | K122: 11
A123: 524 | B123: Nepal | C123: 6 | D123: 0 | E123: 0 | F123: 2 | G123: 0 | H123: 7 | I123: 27
A124: 499 | B124: Montenegro | C124: 24 | D124: 16 | E124: 11 | F124: 32 | G124: 31 | H124: 28 | I124: 40 | J124: 44 | K124: 31
...

Sheet Participacion
A1: Participacion en las exportaciones mundiales de 081090
A2: Cuota = exportaciones de la economia / exportaciones mundiales del ano. Calculado por formula.
A4: Codigo | B4: Economia | C4: 2016 | D4: 2017 | E4: 2018 | F4: 2019 | G4: 2020 | H4: 2021 | I4: 2022 | J4: 2023 | K4: 2024 | L4: 2025
A5: =TradeMap_Datos!A6 -> 764 | B5: =TradeMap_Datos!B6 -> Tailandia | C5: =IF(TradeMap_Datos!C6="",0,TradeMap_Datos!C6/TradeMap_Datos!C$5) -> 0.1349103 | D5: =IF(TradeMap_Datos!D6="",0,TradeMap_Datos!D6/TradeMap_Datos!D$5) -> 0.18505069 | E5: =IF(TradeMap_Datos!E6="",0,TradeMap_Datos!E6/TradeMap_Datos!E$5) -> 0.16190179 | F5: =IF(TradeMap_Datos!F6="",0,TradeMap_Datos!F6/TradeMap_Datos!F$5) -> 0.17693364 | G5: =IF(TradeMap_Datos!G6="",0,TradeMap_Datos!G6/TradeMap_Datos!G$5) -> 0.15750343 | H5: =IF(TradeMap_Datos!H6="",0,TradeMap_Datos!H6/TradeMap_Datos!H$5) -> 0.18779736 | I5: =IF(TradeMap_Datos!I6="",0,TradeMap_Datos!I6/TradeMap_Datos!I$5) -> 0.17108316 | J5: =IF(TradeMap_Datos!J6="",0,TradeMap_Datos!J6/TradeMap_Datos!J$5) -> 0.15553303 | ... L5: =IF(TradeMap_Datos!L6="",0,TradeMap_Datos!L6/TradeMap_Datos!L$5) -> 0.20449959
A6: =TradeMap_Datos!A7 -> 528 | B6: =TradeMap_Datos!B7 -> Países Bajos | C6: =IF(TradeMap_Datos!C7="",0,TradeMap_Datos!C7/TradeMap_Datos!C$5) -> 0.071227612 | D6: =IF(TradeMap_Datos!D7="",0,TradeMap_Datos!D7/TradeMap_Datos!D$5) -> 0.061686781 | E6: =IF(TradeMap_Datos!E7="",0,TradeMap_Datos!E7/TradeMap_Datos!E$5) -> 0.07243324 | F6: =IF(TradeMap_Datos!F7="",0,TradeMap_Datos!F7/TradeMap_Datos!F$5) -> 0.066106666 | G6: =IF(TradeMap_Datos!G7="",0,TradeMap_Datos!G7/TradeMap_Datos!G$5) -> 0.084652571 | H6: =IF(TradeMap_Datos!H7="",0,TradeMap_Datos!H7/TradeMap_Datos!H$5) -> 0.073698109 | I6: =IF(TradeMap_Datos!I7="",0,TradeMap_Datos!I7/TradeMap_Datos!I$5) -> 0.083059975 | J6: =IF(TradeMap_Datos!J7="",0,TradeMap_Datos!J7/TradeMap_Datos!J$5) -> 0.086817975 | ... L6: =IF(TradeMap_Datos!L7="",0,TradeMap_Datos!L7/TradeMap_Datos!L$5) -> 0.12191438
A7: =TradeMap_Datos!A8 -> 218 | B7: =TradeMap_Datos!B8 -> Ecuador | C7: =IF(TradeMap_Datos!C8="",0,TradeMap_Datos!C8/TradeMap_Datos!C$5) -> 0.0033216884 | D7: =IF(TradeMap_Datos!D8="",0,TradeMap_Datos!D8/TradeMap_Datos!D$5) -> 0.0042649771 | E7: =IF(TradeMap_Datos!E8="",0,TradeMap_Datos!E8/TradeMap_Datos!E$5) -> 0.0096568216 | F7: =IF(TradeMap_Datos!F8="",0,TradeMap_Datos!F8/TradeMap_Datos!F$5) -> 0.01558816 | G7: =IF(TradeMap_Datos!G8="",0,TradeMap_Datos!G8/TradeMap_Datos!G$5) -> 0.023164275 | H7: =IF(TradeMap_Datos!H8="",0,TradeMap_Datos!H8/TradeMap_Datos!H$5) -> 0.022328085 | I7: =IF(TradeMap_Datos!I8="",0,TradeMap_Datos!I8/TradeMap_Datos!I$5) -> 0.034468388 | J7: =IF(TradeMap_Datos!J8="",0,TradeMap_Datos!J8/TradeMap_Datos!J$5) -> 0.050783058 | ... L7: =IF(TradeMap_Datos!L8="",0,TradeMap_Datos!L8/TradeMap_Datos!L$5) -> 0.10655536
A8: =TradeMap_Datos!A9 -> 156 | B8: =TradeMap_Datos!B9 -> China | C8: =IF(TradeMap_Datos!C9="",0,TradeMap_Datos!C9/TradeMap_Datos!C$5) -> 0.054555841 | D8: =IF(TradeMap_Datos!D9="",0,TradeMap_Datos!D9/TradeMap_Datos!D$5) -> 0.03300119 | E8: =IF(TradeMap_Datos!E9="",0,TradeMap_Datos!E9/TradeMap_Datos!E$5) -> 0.040445556 | F8: =IF(TradeMap_Datos!F9="",0,TradeMap_Datos!F9/TradeMap_Datos!F$5) -> 0.055119693 | G8: =IF(TradeMap_Datos!G9="",0,TradeMap_Datos!G9/TradeMap_Datos!G$5) -> 0.062680289 | H8: =IF(TradeMap_Datos!H9="",0,TradeMap_Datos!H9/TradeMap_Datos!H$5) -> 0.056357772 | I8: =IF(TradeMap_Datos!I9="",0,TradeMap_Datos!I9/TradeMap_Datos!I$5) -> 0.057260921 | J8: =IF(TradeMap_Datos!J9="",0,TradeMap_Datos!J9/TradeMap_Datos!J$5) -> 0.060023505 | ... L8: =IF(TradeMap_Datos!L9="",0,TradeMap_Datos!L9/TradeMap_Datos!L$5) -> 0.07835239
A9: =TradeMap_Datos!A10 -> 792 | B9: =TradeMap_Datos!B10 -> Türkiye | C9: =IF(TradeMap_Datos!C10="",0,TradeMap_Datos!C10/TradeMap_Datos!C$5) -> 0.033857644 | D9: =IF(TradeMap_Datos!D10="",0,TradeMap_Datos!D10/TradeMap_Datos!D$5) -> 0.025389465 | E9: =IF(TradeMap_Datos!E10="",0,TradeMap_Datos!E10/TradeMap_Datos!E$5) -> 0.029077392 | F9: =IF(TradeMap_Datos!F10="",0,TradeMap_Datos!F10/TradeMap_Datos!F$5) -> 0.022100017 | G9: =IF(TradeMap_Datos!G10="",0,TradeMap_Datos!G10/TradeMap_Datos!G$5) -> 0.031511983 | H9: =IF(TradeMap_Datos!H10="",0,TradeMap_Datos!H10/TradeMap_Datos!H$5) -> 0.030123555 | I9: =IF(TradeMap_Datos!I10="",0,TradeMap_Datos!I10/TradeMap_Datos!I$5) -> 0.033744716 | J9: =IF(TradeMap_Datos!J10="",0,TradeMap_Datos!J10/TradeMap_Datos!J$5) -> 0.03712238 | ... L9: =IF(TradeMap_Datos!L10="",0,TradeMap_Datos!L10/TradeMap_Datos!L$5) -> 0.052402453
A10: =TradeMap_Datos!A11 -> 818 | B10: =TradeMap_Datos!B11 -> Egipto | C10: =IF(TradeMap_Datos!C11="",0,TradeMap_Datos!C11/TradeMap_Datos!C$5) -> 0.041511037 | D10: =IF(TradeMap_Datos!D11="",0,TradeMap_Datos!D11/TradeMap_Datos!D$5) -> 0.025528804 | E10: =IF(TradeMap_Datos!E11="",0,TradeMap_Datos!E11/TradeMap_Datos!E$5) -> 0.019435737 | F10: =IF(TradeMap_Datos!F11="",0,TradeMap_Datos!F11/TradeMap_Datos!F$5) -> 0.016454681 | G10: =IF(TradeMap_Datos!G11="",0,TradeMap_Datos!G11/TradeMap_Datos!G$5) -> 0.016889123 | H10: =IF(TradeMap_Datos!H11="",0,TradeMap_Datos!H11/TradeMap_Datos!H$5) -> 0.016104428 | I10: =IF(TradeMap_Datos!I11="",0,TradeMap_Datos!I11/TradeMap_Datos!I$5) -> 0.037314092 | J10: =IF(TradeMap_Datos!J11="",0,TradeMap_Datos!J11/TradeMap_Datos!J$5) -> 0.039822832 | ... L10: =IF(TradeMap_Datos!L11="",0,TradeMap_Datos!L11/TradeMap_Datos!L$5) -> 0.052337956
A11: =TradeMap_Datos!A12 -> 724 | B11: =TradeMap_Datos!B12 -> España | C11: =IF(TradeMap_Datos!C12="",0,TradeMap_Datos!C12/TradeMap_Datos!C$5) -> 0.029009239 | D11: =IF(TradeMap_Datos!D12="",0,TradeMap_Datos!D12/TradeMap_Datos!D$5) -> 0.03096903 | E11: =IF(TradeMap_Datos!E12="",0,TradeMap_Datos!E12/TradeMap_Datos!E$5) -> 0.023224451 | F11: =IF(TradeMap_Datos!F12="",0,TradeMap_Datos!F12/TradeMap_Datos!F$5) -> 0.021645257 | G11: =IF(TradeMap_Datos!G12="",0,TradeMap_Datos!G12/TradeMap_Datos!G$5) -> 0.021963783 | H11: =IF(TradeMap_Datos!H12="",0,TradeMap_Datos!H12/TradeMap_Datos!H$5) -> 0.022522686 | I11: =IF(TradeMap_Datos!I12="",0,TradeMap_Datos!I12/TradeMap_Datos!I$5) -> 0.024805563 | J11: =IF(TradeMap_Datos!J12="",0,TradeMap_Datos!J12/TradeMap_Datos!J$5) -> 0.025514622 | ... L11: =IF(TradeMap_Datos!L12="",0,TradeMap_Datos!L12/TradeMap_Datos!L$5) -> 0.044031857
A12: =TradeMap_Datos!A13 -> 604 | B12: =TradeMap_Datos!B13 -> Perú | C12: =IF(TradeMap_Datos!C13="",0,TradeMap_Datos!C13/TradeMap_Datos!C$5) -> 0.01337379 | D12: =IF(TradeMap_Datos!D13="",0,TradeMap_Datos!D13/TradeMap_Datos!D$5) -> 0.015633639 | E12: =IF(TradeMap_Datos!E13="",0,TradeMap_Datos!E13/TradeMap_Datos!E$5) -> 0.017992599 | F12: =IF(TradeMap_Datos!F13="",0,TradeMap_Datos!F13/TradeMap_Datos!F$5) -> 0.015355827 | G12: =IF(TradeMap_Datos!G13="",0,TradeMap_Datos!G13/TradeMap_Datos!G$5) -> 0.015943576 | H12: =IF(TradeMap_Datos!H13="",0,TradeMap_Datos!H13/TradeMap_Datos!H$5) -> 0.018701873 | I12: =IF(TradeMap_Datos!I13="",0,TradeMap_Datos!I13/TradeMap_Datos!I$5) -> 0.023607371 | J12: =IF(TradeMap_Datos!J13="",0,TradeMap_Datos!J13/TradeMap_Datos!J$5) -> 0.02412255 | ... L12: =IF(TradeMap_Datos!L13="",0,TradeMap_Datos!L13/TradeMap_Datos!L$5) -> 0.037938911
A13: =TradeMap_Datos!A14 -> 699 | B13: =TradeMap_Datos!B14 -> India | C13: =IF(TradeMap_Datos!C14="",0,TradeMap_Datos!C14/TradeMap_Datos!C$5) -> 0.026391314 | D13: =IF(TradeMap_Datos!D14="",0,TradeMap_Datos!D14/TradeMap_Datos!D$5) -> 0.028566344 | E13: =IF(TradeMap_Datos!E14="",0,TradeMap_Datos!E14/TradeMap_Datos!E$5) -> 0.024894589 | F13: =IF(TradeMap_Datos!F14="",0,TradeMap_Datos!F14/TradeMap_Datos!F$5) -> 0.025783804 | G13: =IF(TradeMap_Datos!G14="",0,TradeMap_Datos!G14/TradeMap_Datos!G$5) -> 0.022464676 | H13: =IF(TradeMap_Datos!H14="",0,TradeMap_Datos!H14/TradeMap_Datos!H$5) -> 0.02145473 | I13: =IF(TradeMap_Datos!I14="",0,TradeMap_Datos!I14/TradeMap_Datos!I$5) -> 0.022108217 | J13: =IF(TradeMap_Datos!J14="",0,TradeMap_Datos!J14/TradeMap_Datos!J$5) -> 0.021491118 | ... L13: =IF(TradeMap_Datos!L14="",0,TradeMap_Datos!L14/TradeMap_Datos!L$5) -> 0.037129115
A14: =TradeMap_Datos!A15 -> 170 | B14: =TradeMap_Datos!B15 -> Colombia | C14: =IF(TradeMap_Datos!C15="",0,TradeMap_Datos!C15/TradeMap_Datos!C$5) -> 0.01852585 | D14: =IF(TradeMap_Datos!D15="",0,TradeMap_Datos!D15/TradeMap_Datos!D$5) -> 0.016188647 | E14: =IF(TradeMap_Datos!E15="",0,TradeMap_Datos!E15/TradeMap_Datos!E$5) -> 0.018924104 | F14: =IF(TradeMap_Datos!F15="",0,TradeMap_Datos!F15/TradeMap_Datos!F$5) -> 0.018054673 | G14: =IF(TradeMap_Datos!G15="",0,TradeMap_Datos!G15/TradeMap_Datos!G$5) -> 0.019228621 | H14: =IF(TradeMap_Datos!H15="",0,TradeMap_Datos!H15/TradeMap_Datos!H$5) -> 0.021063065 | I14: =IF(TradeMap_Datos!I15="",0,TradeMap_Datos!I15/TradeMap_Datos!I$5) -> 0.027965821 | J14: =IF(TradeMap_Datos!J15="",0,TradeMap_Datos!J15/TradeMap_Datos!J$5) -> 0.026873272 | ... L14: =IF(TradeMap_Datos!L15="",0,TradeMap_Datos!L15/TradeMap_Datos!L$5) -> 0.036283798
A15: =TradeMap_Datos!A16 -> 842 | B15: =TradeMap_Datos!B16 -> Estados Unidos de América | C15: =IF(TradeMap_Datos!C16="",0,TradeMap_Datos!C16/TradeMap_Datos!C$5) -> 0.020246451 | D15: =IF(TradeMap_Datos!D16="",0,TradeMap_Datos!D16/TradeMap_Datos!D$5) -> 0.016629366 | E15: =IF(TradeMap_Datos!E16="",0,TradeMap_Datos!E16/TradeMap_Datos!E$5) -> 0.017201387 | F15: =IF(TradeMap_Datos!F16="",0,TradeMap_Datos!F16/TradeMap_Datos!F$5) -> 0.015706127 | G15: =IF(TradeMap_Datos!G16="",0,TradeMap_Datos!G16/TradeMap_Datos!G$5) -> 0.01946532 | H15: =IF(TradeMap_Datos!H16="",0,TradeMap_Datos!H16/TradeMap_Datos!H$5) -> 0.016370017 | I15: =IF(TradeMap_Datos!I16="",0,TradeMap_Datos!I16/TradeMap_Datos!I$5) -> 0.017313186 | J15: =IF(TradeMap_Datos!J16="",0,TradeMap_Datos!J16/TradeMap_Datos!J$5) -> 0.016929316 | ... L15: =IF(TradeMap_Datos!L16="",0,TradeMap_Datos!L16/TradeMap_Datos!L$5) -> 0.023407133
A16: =TradeMap_Datos!A17 -> 056 | B16: =TradeMap_Datos!B17 -> Bélgica | C16: =IF(TradeMap_Datos!C17="",0,TradeMap_Datos!C17/TradeMap_Datos!C$5) -> 0.017276807 | D16: =IF(TradeMap_Datos!D17="",0,TradeMap_Datos!D17/TradeMap_Datos!D$5) -> 0.0088644724 | E16: =IF(TradeMap_Datos!E17="",0,TradeMap_Datos!E17/TradeMap_Datos!E$5) -> 0.01646958 | F16: =IF(TradeMap_Datos!F17="",0,TradeMap_Datos!F17/TradeMap_Datos!F$5) -> 0.032962718 | G16: =IF(TradeMap_Datos!G17="",0,TradeMap_Datos!G17/TradeMap_Datos!G$5) -> 0.011644499 | H16: =IF(TradeMap_Datos!H17="",0,TradeMap_Datos!H17/TradeMap_Datos!H$5) -> 0.009917945 | I16: =IF(TradeMap_Datos!I17="",0,TradeMap_Datos!I17/TradeMap_Datos!I$5) -> 0.01446012 | J16: =IF(TradeMap_Datos!J17="",0,TradeMap_Datos!J17/TradeMap_Datos!J$5) -> 0.011851771 | ... L16: =IF(TradeMap_Datos!L17="",0,TradeMap_Datos!L17/TradeMap_Datos!L$5) -> 0.018258586
... A164: =TradeMap_Datos!A165 -> 020 | B164: =TradeMap_Datos!B165 -> Andorra | C164: =IF(TradeMap_Datos!C165="",0,TradeMap_Datos!C165/TradeMap_Datos!C$5) -> 0 | D164: =IF(TradeMap_Datos!D165="",0,TradeMap_Datos!D165/TradeMap_Datos!D$5) -> 0 | E164: =IF(TradeMap_Datos!E165="",0,TradeMap_Datos!E165/TradeMap_Datos!E$5) -> 0 | F164: =IF(TradeMap_Datos!F165="",0,TradeMap_Datos!F165/TradeMap_Datos!F$5) -> 0 | G164: =IF(TradeMap_Datos!G165="",0,TradeMap_Datos!G165/TradeMap_Datos!G$5) -> 0 | H164: =IF(TradeMap_Datos!H165="",0,TradeMap_Datos!H165/TradeMap_Datos!H$5) -> 0 | I164: =IF(TradeMap_Datos!I165="",0,TradeMap_Datos!I165/TradeMap_Datos!I$5) -> 0 | J164: =IF(TradeMap_Datos!J165="",0,TradeMap_Datos!J165/TradeMap_Datos!J$5) -> 2.717299e-07 | ... L164: =IF(TradeMap_Datos!L165="",0,TradeMap_Datos!L165/TradeMap_Datos!L$5) -> 0
A166: Las celdas sin dato se fijan en 0 para que las sumas de la hoja HHI_Oferta no se interrumpan.

Sheet HHI_Oferta
A1: Concentracion de la oferta mundial de 081090
A2: HHI = suma de los cuadrados de las cuotas de exportacion de las 160 economias. Umbrales: >0,18 concentrado; 0,15-0,18 moderado; <0,15 fragmentado.
A4: Ano | B4: Exportaciones mundiales (USD miles) | C4: Economias con dato | D4: HHI (0-1) | E4: HHI (escala 0-10.000) | F4: Numero equivalente de exportadores | G4: Lectura del umbral
A5: 2016 | B5: =TradeMap_Datos!C5 -> 3079157 | C5: =COUNT(TradeMap_Datos!C6:C165) -> 154 | D5: =SUMPRODUCT(Participacion!C5:C164,Participacion!C5:C164) -> 0.17182639 | E5: =D5*10000 -> 1718.2639 | F5: =IFERROR(1/D5,"") -> 5.8198278 | G5: =IF(D5>0.18,"Concentrado",IF(D5>=0.15,"Moderado","Fragmentado")) -> Moderado
A6: 2017 | B6: =TradeMap_Datos!D5 -> 3832377 | C6: =COUNT(TradeMap_Datos!D6:D165) -> 158 | D6: =SUMPRODUCT(Participacion!D5:D164,Participacion!D5:D164) -> 0.19383748 | E6: =D6*10000 -> 1938.3748 | F6: =IFERROR(1/D6,"") -> 5.158961 | G6: =IF(D6>0.18,"Concentrado",IF(D6>=0.15,"Moderado","Fragmentado")) -> Concentrado
A7: 2018 | B7: =TradeMap_Datos!E5 -> 3955960 | C7: =COUNT(TradeMap_Datos!E6:E165) -> 155 | D7: =SUMPRODUCT(Participacion!E5:E164,Participacion!E5:E164) -> 0.19421688 | E7: =D7*10000 -> 1942.1688 | F7: =IFERROR(1/D7,"") -> 5.1488831 | G7: =IF(D7>0.18,"Concentrado",IF(D7>=0.15,"Moderado","Fragmentado")) -> Concentrado
A8: 2019 | B8: =TradeMap_Datos!F5 -> 4441897 | C8: =COUNT(TradeMap_Datos!F6:F165) -> 152 | D8: =SUMPRODUCT(Participacion!F5:F164,Participacion!F5:F164) -> 0.16609729 | E8: =D8*10000 -> 1660.9729 | F8: =IFERROR(1/D8,"") -> 6.0205676 | G8: =IF(D8>0.18,"Concentrado",IF(D8>=0.15,"Moderado","Fragmentado")) -> Moderado
A9: 2020 | B9: =TradeMap_Datos!G5 -> 4000859 | C9: =COUNT(TradeMap_Datos!G6:G165) -> 151 | D9: =SUMPRODUCT(Participacion!G5:G164,Participacion!G5:G164) -> 0.15401487 | E9: =D9*10000 -> 1540.1487 | F9: =IFERROR(1/D9,"") -> 6.4928794 | G9: =IF(D9>0.18,"Concentrado",IF(D9>=0.15,"Moderado","Fragmentado")) -> Moderado
A10: 2021 | B10: =TradeMap_Datos!H5 -> 4465542 | C10: =COUNT(TradeMap_Datos!H6:H165) -> 151 | D10: =SUMPRODUCT(Participacion!H5:H164,Participacion!H5:H164) -> 0.13549346 | E10: =D10*10000 -> 1354.9346 | F10: =IFERROR(1/D10,"") -> 7.3804302 | G10: =IF(D10>0.18,"Concentrado",IF(D10>=0.15,"Moderado","Fragmentado")) -> Fragmentado
A11: 2022 | B11: =TradeMap_Datos!I5 -> 3531990 | C11: =COUNT(TradeMap_Datos!I6:I165) -> 149 | D11: =SUMPRODUCT(Participacion!I5:I164,Participacion!I5:I164) -> 0.10561581 | E11: =D11*10000 -> 1056.1581 | F11: =IFERROR(1/D11,"") -> 9.4682792 | G11: =IF(D11>0.18,"Concentrado",IF(D11>=0.15,"Moderado","Fragmentado")) -> Fragmentado
A12: 2023 | B12: =TradeMap_Datos!J5 -> 3680125 | C12: =COUNT(TradeMap_Datos!J6:J165) -> 148 | D12: =SUMPRODUCT(Participacion!J5:J164,Participacion!J5:J164) -> 0.10919018 | E12: =D12*10000 -> 1091.9018 | F12: =IFERROR(1/D12,"") -> 9.1583331 | G12: =IF(D12>0.18,"Concentrado",IF(D12>=0.15,"Moderado","Fragmentado")) -> Fragmentado
A13: 2024 | B13: =TradeMap_Datos!K5 -> 3904393 | C13: =COUNT(TradeMap_Datos!K6:K165) -> 139 | D13: =SUMPRODUCT(Participacion!K5:K164,Participacion!K5:K164) -> 0.099086344 | E13: =D13*10000 -> 990.86344 | F13: =IFERROR(1/D13,"") -> 10.092208 | G13: =IF(D13>0.18,"Concentrado",IF(D13>=0.15,"Moderado","Fragmentado")) -> Fragmentado
A14: 2025 | B14: =TradeMap_Datos!L5 -> 3209449 | C14: =COUNT(TradeMap_Datos!L6:L165) -> 109 | D14: =SUMPRODUCT(Participacion!L5:L164,Participacion!L5:L164) -> 0.088382095 | E14: =D14*10000 -> 883.82095 | F14: =IFERROR(1/D14,"") -> 11.314509 | G14: =IF(D14>0.18,"Concentrado",IF(D14>=0.15,"Moderado","Fragmentado")) -> Fragmentado
A16: Numero equivalente = 1 / HHI: cuantos competidores del mismo tamano producirian esa misma concentracion.

Sheet Andinos
A1: Colombia frente a sus competidores andinos en 081090
A2: Valores tomados de la hoja TradeMap_Datos mediante INDICE y COINCIDIR.
A4: Ano | B4: Colombia (USD miles) | C4: Ecuador (USD miles) | D4: Peru (USD miles) | E4: Cuota Colombia | F4: Cuota Ecuador | G4: Cuota Peru | H4: Ecuador / Colombia (veces)
A5: 2016 | B5: =INDEX(TradeMap_Datos!C$6:C$165,MATCH("Colombia",TradeMap_Datos!$B$6:$B$165,0)) -> 57044 | C5: =INDEX(TradeMap_Datos!C$6:C$165,MATCH("Ecuador",TradeMap_Datos!$B$6:$B$165,0)) -> 10228 | D5: =INDEX(TradeMap_Datos!C$6:C$165,MATCH("Perú",TradeMap_Datos!$B$6:$B$165,0)) -> 41180 | E5: =B5/TradeMap_Datos!C$5 -> 0.01852585 | F5: =C5/TradeMap_Datos!C$5 -> 0.0033216884 | G5: =D5/TradeMap_Datos!C$5 -> 0.01337379 | H5: =IFERROR(C5/B5,"") -> 0.17930019
A6: 2017 | B6: =INDEX(TradeMap_Datos!D$6:D$165,MATCH("Colombia",TradeMap_Datos!$B$6:$B$165,0)) -> 62041 | C6: =INDEX(TradeMap_Datos!D$6:D$165,MATCH("Ecuador",TradeMap_Datos!$B$6:$B$165,0)) -> 16345 | D6: =INDEX(TradeMap_Datos!D$6:D$165,MATCH("Perú",TradeMap_Datos!$B$6:$B$165,0)) -> 59914 | E6: =B6/TradeMap_Datos!D$5 -> 0.016188647 | F6: =C6/TradeMap_Datos!D$5 -> 0.0042649771 | G6: =D6/TradeMap_Datos!D$5 -> 0.015633639 | H6: =IFERROR(C6/B6,"") -> 0.26345481
A7: 2018 | B7: =INDEX(TradeMap_Datos!E$6:E$165,MATCH("Colombia",TradeMap_Datos!$B$6:$B$165,0)) -> 74863 | C7: =INDEX(TradeMap_Datos!E$6:E$165,MATCH("Ecuador",TradeMap_Datos!$B$6:$B$165,0)) -> 38202 | D7: =INDEX(TradeMap_Datos!E$6:E$165,MATCH("Perú",TradeMap_Datos!$B$6:$B$165,0)) -> 71178 | E7: =B7/TradeMap_Datos!E$5 -> 0.018924104 | F7: =C7/TradeMap_Datos!E$5 -> 0.0096568216 | G7: =D7/TradeMap_Datos!E$5 -> 0.017992599 | H7: =IFERROR(C7/B7,"") -> 0.51029213
A8: 2019 | B8: =INDEX(TradeMap_Datos!F$6:F$165,MATCH("Colombia",TradeMap_Datos!$B$6:$B$165,0)) -> 80197 | C8: =INDEX(TradeMap_Datos!F$6:F$165,MATCH("Ecuador",TradeMap_Datos!$B$6:$B$165,0)) -> 69241 | D8: =INDEX(TradeMap_Datos!F$6:F$165,MATCH("Perú",TradeMap_Datos!$B$6:$B$165,0)) -> 68209 | E8: =B8/TradeMap_Datos!F$5 -> 0.018054673 | F8: =C8/TradeMap_Datos!F$5 -> 0.01558816 | G8: =D8/TradeMap_Datos!F$5 -> 0.015355827 | H8: =IFERROR(C8/B8,"") -> 0.86338641
A9: 2020 | B9: =INDEX(TradeMap_Datos!G$6:G$165,MATCH("Colombia",TradeMap_Datos!$B$6:$B$165,0)) -> 76931 | C9: =INDEX(TradeMap_Datos!G$6:G$165,MATCH("Ecuador",TradeMap_Datos!$B$6:$B$165,0)) -> 92677 | D9: =INDEX(TradeMap_Datos!G$6:G$165,MATCH("Perú",TradeMap_Datos!$B$6:$B$165,0)) -> 63788 | E9: =B9/TradeMap_Datos!G$5 -> 0.019228621 | F9: =C9/TradeMap_Datos!G$5 -> 0.023164275 | G9: =D9/TradeMap_Datos!G$5 -> 0.015943576 | H9: =IFERROR(C9/B9,"") -> 1.2046769
A10: 2021 | B10: =INDEX(TradeMap_Datos!H$6:H$165,MATCH("Colombia",TradeMap_Datos!$B$6:$B$165,0)) -> 94058 | C10: =INDEX(TradeMap_Datos!H$6:H$165,MATCH("Ecuador",TradeMap_Datos!$B$6:$B$165,0)) -> 99707 | D10: =INDEX(TradeMap_Datos!H$6:H$165,MATCH("Perú",TradeMap_Datos!$B$6:$B$165,0)) -> 83514 | E10: =B10/TradeMap_Datos!H$5 -> 0.021063065 | F10: =C10/TradeMap_Datos!H$5 -> 0.022328085 | G10: =D10/TradeMap_Datos!H$5 -> 0.018701873 | H10: =IFERROR(C10/B10,"") -> 1.0600587
A11: 2022 | B11: =INDEX(TradeMap_Datos!I$6:I$165,MATCH("Colombia",TradeMap_Datos!$B$6:$B$165,0)) -> 98775 | C11: =INDEX(TradeMap_Datos!I$6:I$165,MATCH("Ecuador",TradeMap_Datos!$B$6:$B$165,0)) -> 121742 | D11: =INDEX(TradeMap_Datos!I$6:I$165,MATCH("Perú",TradeMap_Datos!$B$6:$B$165,0)) -> 83381 | E11: =B11/TradeMap_Datos!I$5 -> 0.027965821 | F11: =C11/TradeMap_Datos!I$5 -> 0.034468388 | G11: =D11/TradeMap_Datos!I$5 -> 0.023607371 | H11: =IFERROR(C11/B11,"") -> 1.2325183
A12: 2023 | B12: =INDEX(TradeMap_Datos!J$6:J$165,MATCH("Colombia",TradeMap_Datos!$B$6:$B$165,0)) -> 98897 | C12: =INDEX(TradeMap_Datos!J$6:J$165,MATCH("Ecuador",TradeMap_Datos!$B$6:$B$165,0)) -> 186888 | D12: =INDEX(TradeMap_Datos!J$6:J$165,MATCH("Perú",TradeMap_Datos!$B$6:$B$165,0)) -> 88774 | E12: =B12/TradeMap_Datos!J$5 -> 0.026873272 | F12: =C12/TradeMap_Datos!J$5 -> 0.050783058 | G12: =D12/TradeMap_Datos!J$5 -> 0.02412255 | H12: =IFERROR(C12/B12,"") -> 1.8897237
A13: 2024 | B13: =INDEX(TradeMap_Datos!K$6:K$165,MATCH("Colombia",TradeMap_Datos!$B$6:$B$165,0)) -> 106407 | C13: =INDEX(TradeMap_Datos!K$6:K$165,MATCH("Ecuador",TradeMap_Datos!$B$6:$B$165,0)) -> 233457 | D13: =INDEX(TradeMap_Datos!K$6:K$165,MATCH("Perú",TradeMap_Datos!$B$6:$B$165,0)) -> 88624 | E13: =B13/TradeMap_Datos!K$5 -> 0.027253148 | F13: =C13/TradeMap_Datos!K$5 -> 0.059793417 | G13: =D13/TradeMap_Datos!K$5 -> 0.022698535 | H13: =IFERROR(C13/B13,"") -> 2.1940004
A14: 2025 | B14: =INDEX(TradeMap_Datos!L$6:L$165,MATCH("Colombia",TradeMap_Datos!$B$6:$B$165,0)) -> 116451 | C14: =INDEX(TradeMap_Datos!L$6:L$165,MATCH("Ecuador",TradeMap_Datos!$B$6:$B$165,0)) -> 341984 | D14: =INDEX(TradeMap_Datos!L$6:L$165,MATCH("Perú",TradeMap_Datos!$B$6:$B$165,0)) -> 121763 | E14: =B14/TradeMap_Datos!L$5 -> 0.036283798 | F14: =C14/TradeMap_Datos!L$5 -> 0.10655536 | G14: =D14/TradeMap_Datos!L$5 -> 0.037938911 | H14: =IFERROR(C14/B14,"") -> 2.9367202
A16: CAGR | B16: =IFERROR((B14/B5)^(1/9)-1,"") -> 0.082522739 | C16: =IFERROR((C14/C5)^(1/9)-1,"") -> 0.47692088 | D16: =IFERROR((D14/D5)^(1/9)-1,"") -> 0.12801359
A18: CAGR = tasa de crecimiento anual compuesta entre el primero y el ultimo ano de la serie.
A19: El ultimo ano de la serie tiene cobertura parcial (ver hoja Cobertura); para comparaciones definitivas conviene usar el penultimo.

Sheet Cobertura
A1: Cobertura y calidad de la descarga de Trade Map
A2: Cuantas economias reportan cada ano. El ano en curso siempre llega incompleto.
A4: Ano | B4: Economias que reportan | C4: Economias sin dato | D4: Cobertura | E4: Apto para ranking
A5: 2016 | B5: =COUNT(TradeMap_Datos!C6:C165) -> 154 | C5: =160-B5 -> 6 | D5: =B5/160 -> 0.9625 | E5: =IF(D5>=0.85,"Si","No - cobertura parcial") -> Si
A6: 2017 | B6: =COUNT(TradeMap_Datos!D6:D165) -> 158 | C6: =160-B6 -> 2 | D6: =B6/160 -> 0.9875 | E6: =IF(D6>=0.85,"Si","No - cobertura parcial") -> Si
A7: 2018 | B7: =COUNT(TradeMap_Datos!E6:E165) -> 155 | C7: =160-B7 -> 5 | D7: =B7/160 -> 0.96875 | E7: =IF(D7>=0.85,"Si","No - cobertura parcial") -> Si
A8: 2019 | B8: =COUNT(TradeMap_Datos!F6:F165) -> 152 | C8: =160-B8 -> 8 | D8: =B8/160 -> 0.95 | E8: =IF(D8>=0.85,"Si","No - cobertura parcial") -> Si
A9: 2020 | B9: =COUNT(TradeMap_Datos!G6:G165) -> 151 | C9: =160-B9 -> 9 | D9: =B9/160 -> 0.94375 | E9: =IF(D9>=0.85,"Si","No - cobertura parcial") -> Si
A10: 2021 | B10: =COUNT(TradeMap_Datos!H6:H165) -> 151 | C10: =160-B10 -> 9 | D10: =B10/160 -> 0.94375 | E10: =IF(D10>=0.85,"Si","No - cobertura parcial") -> Si
A11: 2022 | B11: =COUNT(TradeMap_Datos!I6:I165) -> 149 | C11: =160-B11 -> 11 | D11: =B11/160 -> 0.93125 | E11: =IF(D11>=0.85,"Si","No - cobertura parcial") -> Si
A12: 2023 | B12: =COUNT(TradeMap_Datos!J6:J165) -> 148 | C12: =160-B12 -> 12 | D12: =B12/160 -> 0.925 | E12: =IF(D12>=0.85,"Si","No - cobertura parcial") -> Si
A13: 2024 | B13: =COUNT(TradeMap_Datos!K6:K165) -> 139 | C13: =160-B13 -> 21 | D13: =B13/160 -> 0.86875 | E13: =IF(D13>=0.85,"Si","No - cobertura parcial") -> Si
A14: 2025 | B14: =COUNT(TradeMap_Datos!L6:L165) -> 109 | C14: =160-B14 -> 51 | D14: =B14/160 -> 0.68125 | E14: =IF(D14>=0.85,"Si","No - cobertura parcial") -> No - cobertura parcial

Sheet Conjunto_A
A1: Conjunto A - Comercio mundial de pasifloras por region (USD miles)
A2: Estimacion del equipo publicada en la ficha tecnica, seccion 3.1.
A4: Region | B4: 2019 | C4: 2020 | D4: 2021 | E4: 2022 | F4: 2023 | G4: 2024
A5: America Latina | B5: 45200 | C5: 48100 | D5: 52300 | E5: 58900 | F5: 61200 | G5: 64500
A6: Union Europea | B6: 32100 | C6: 31800 | D6: 35400 | E6: 39100 | F6: 41000 | G6: 43200
A7: Resto del mundo | B7: 18400 | C7: 19200 | D7: 21000 | E7: 23500 | F7: 25100 | G7: 26800
A8: Total | B8: =SUM(B5:B7) -> 95700 | C8: =SUM(C5:C7) -> 99100 | D8: =SUM(D5:D7) -> 108700 | E8: =SUM(E5:E7) -> 121500 | F8: =SUM(F5:F7) -> 127300 | G8: =SUM(G5:G7) -> 134500
A9: Participacion America Latina | B9: =B5/B8 -> 0.4723093 | C9: =C5/C8 -> 0.48536831 | D9: =D5/D8 -> 0.48114075 | E9: =E5/E8 -> 0.48477366 | F9: =F5/F8 -> 0.48075412 | G9: =G5/G8 -> 0.4795539
A10: CAGR del total | B10: =(G8/B8)^(1/5)-1 -> 0.070439359
A12: Fuente: ficha tecnica del Equipo 6, seccion 3.1. Cifras estimadas por el equipo, no descargadas de una base oficial; ver hoja Supuestos.

Sheet Conjunto_B
A1: Conjunto B - Variables macroeconomicas de Colombia
A2: Estimacion del equipo publicada en la ficha tecnica, seccion 3.1. Fuente declarada: Banco Mundial (WDI).
A4: Variable | B4: 2019 | C4: 2020 | D4: 2021 | E4: 2022 | F4: 2023 | G4: 2024
A5: PIB agricola (crecimiento %) | B5: 3.1 | C5: -0.8 | D5: 3.5 | E5: 1.2 | F5: 1.8 | G5: 2.4
A6: Tasa de cambio (TRM promedio) | B6: 3281 | C6: 3693 | D6: 3743 | E6: 4255 | F6: 4325 | G6: 3950
A7: Inflacion IPC (%) | B7: 3.8 | C7: 1.61 | D7: 5.62 | E7: 13.12 | F7: 9.28 | G7: 5.5

Sheet Conjunto_C
A1: Conjunto C - Produccion de pasifloras y curuba, e imputacion comercial
A2: El valor imputado se calcula por formula sobre el factor declarado de la celda B6.
A4: Factor de imputacion declarado (supuesto S1) | B4: 0.038 | C4: Se aplica sobre la fila America Latina del Conjunto A
A6: Ano | B6: Produccion pasifloras (ton) | C6: Produccion curuba (ton) | D6: Participacion curuba en pasifloras | E6: Base comercial America Latina (USD miles) | F6: Valor imputado calculado (USD miles) | G6: Valor publicado en la ficha (USD miles)
A7: 2019 | B7: 145000 | C7: 18200 | D7: =C7/B7 -> 0.12551724 | E7: =Conjunto_A!B5 -> 45200 | F7: =E7*$B$4 -> 1717.6 | G7: 1717.6
A8: 2020 | B8: 148200 | C8: 18500 | D8: =C8/B8 -> 0.12483131 | E8: =Conjunto_A!C5 -> 48100 | F8: =E8*$B$4 -> 1827.8 | G8: 1827.8
A9: 2021 | B9: 152000 | C9: 19100 | D9: =C9/B9 -> 0.12565789 | E9: =Conjunto_A!D5 -> 52300 | F9: =E9*$B$4 -> 1987.4 | G9: 1987.4
A10: 2022 | B10: 155400 | C10: 19400 | D10: =C10/B10 -> 0.12483912 | E10: =Conjunto_A!E5 -> 58900 | F10: =E10*$B$4 -> 2238.2 | G10: 2238.2
A11: 2023 | B11: 158100 | C11: 19800 | D11: =C11/B11 -> 0.12523719 | E11: =Conjunto_A!F5 -> 61200 | F11: =E11*$B$4 -> 2325.6 | G11: 2325.6
A12: 2024 | B12: 162000 | C12: 20200 | D12: =C12/B12 -> 0.12469136 | E12: =Conjunto_A!G5 -> 64500 | F12: =E12*$B$4 -> 2451 | G12: 2451
A13: Diferencia maxima | F13: =MAX(ABS(F7-G7),ABS(F8-G8),ABS(F9-G9),ABS(F10-G10),ABS(F11-G11),ABS(F12-G12)) -> 0
A15: El supuesto S1 aplica un factor comercial del 3,8 %. La participacion productiva de la curuba en el total de pasifloras (columna D) ronda el 12,5 %: son magnitudes distintas y no intercambiables (ver hoja Supuestos).

Sheet Posicion_Comercial
A1: Posicion comercial de los seis mercados (subpartida 0810.90 agregada)
A2: IBCR e indice de Grubel-Lloyd calculados por formula a partir de X y M.
A4: Pais | B4: M (USD miles) | C4: X (USD miles) | D4: IBCR calculado | E4: GL = 1-|IBCR| | F4: IAC (%) | G4: IBCR publicado en la ficha | H4: Clasificacion comercial
A5: Colombia | B5: 450 | C5: 2091.3 | D5: =(C5-B5)/(C5+B5) -> 0.64585055 | E5: =1-ABS(D5) -> 0.35414945 | F5: 38.2 | G5: 0.646 | H5: Pais origen / exportador neto
A6: Paises Bajos | B6: 18400 | C6: 15200 | D6: =(C6-B6)/(C6+B6) -> -0.095238095 | E6: =1-ABS(D6) -> 0.9047619 | F6: 154.2 | G6: -0.095 | H6: Hub de reexportacion / distribuidor UE
A7: Espana | B7: 8200 | C7: 3100 | D7: =(C7-B7)/(C7+B7) -> -0.45132743 | E7: =1-ABS(D7) -> 0.54867257 | F7: 62.8 | G7: -0.451 | H7: Mercado mixto (consumo / reexportacion regional)
A8: Alemania | B8: 12500 | C8: 1800 | D8: =(C8-B8)/(C8+B8) -> -0.74825175 | E8: =1-ABS(D8) -> 0.25174825 | F8: 87.1 | G8: -0.748 | H8: Mercado de consumo final masivo
A9: Canada | B9: 5600 | C9: 120 | D9: =(C9-B9)/(C9+B9) -> -0.95804196 | E9: =1-ABS(D9) -> 0.041958042 | F9: 65.4 | G9: -0.958 | H9: Mercado de consumo final puro
A10: Emiratos Arabes Unidos | B10: 6800 | C10: 2400 | D10: =(C10-B10)/(C10+B10) -> -0.47826087 | E10: =1-ABS(D10) -> 0.52173913 | F10: 168.5 | G10: -0.478 | H10: Hub logistico / reexportacion Medio Oriente
A12: Base alternativa declarada: curuba especifica (Colombia)
A13: Colombia (curuba) | B13: 22.19 | C13: 2091.3 | D13: =(C13-B13)/(C13+B13) -> 0.97900156 | E13: =1-ABS(D13) -> 0.020998443 | H13: M derivada del GL publicado (0,021); ver supuesto S4
A15: Las dos bases no son comparables entre si: la primera agrupa toda la subpartida 0810.90 y la segunda aisla la curuba. Ambas sostienen la misma lectura: Colombia es exportador neto y su comercio de este producto es de una sola via.

Sheet Concentracion
A1: Concentracion y estructura del comercio: curuba frente a gulupa
A2: HHI de destinos, indice de Theil e indice de Grubel-Lloyd. Ficha tecnica, seccion 3.3.
A4: Producto | B4: HHI de destinos | C4: Escala 0-10.000 | D4: Numero equivalente de destinos | E4: Indice de Theil | F4: Grubel-Lloyd | G4: Lectura frente al umbral de 0,18
A5: Curuba (Passiflora mollissima) | B5: 0.0842 | C5: =B5*10000 -> 842 | D5: =1/B5 -> 11.876485 | E5: 1.845 | F5: 0.021 | G5: =IF(B5>0.18,"Concentrado (mercado ancla)",IF(B5>=0.15,"Moderado","Diversificado / fragmentado")) -> Diversificado / fragmentado
A6: Gulupa (Passiflora edulis f. flavicarpa) | B6: 0.4215 | C6: =B6*10000 -> 4215 | D6: =1/B6 -> 2.3724792 | E6: 0.612 | F6: 0.008 | G6: =IF(B6>0.18,"Concentrado (mercado ancla)",IF(B6>=0.15,"Moderado","Diversificado / fragmentado")) -> Concentrado (mercado ancla)
A8: El HHI de destinos mide como se reparten las ventas entre paises compradores; no debe compararse con el HHI de la hoja HHI_Oferta, que mide la concentracion de la oferta mundial.

Sheet Ventaja_Comparativa
A1: Ventaja comparativa revelada: Balassa, RSCA y Lafay
A2: El RSCA se recalcula por formula desde el RCA para verificar la identidad (RCA-1)/(RCA+1).
A4: Producto / sector | B4: Balassa (RCA) | C4: RSCA recalculado | D4: RSCA publicado | E4: Lafay (LFI) | F4: Lectura del umbral
A5: Curuba (Passiflora mollissima) | B5: 12.45 | C5: =(B5-1)/(B5+1) -> 0.85130112 | D5: 0.851 | E5: 1.12 | F5: =IF(B5>1,"Ventaja comparativa revelada","Desventaja comparativa") -> Ventaja comparativa revelada
A6: Sector pasifloras Colombia (agregado) | B6: 18.3 | C6: =(B6-1)/(B6+1) -> 0.89637306 | D6: 0.896 | E6: 2.45 | F6: =IF(B6>1,"Ventaja comparativa revelada","Desventaja comparativa") -> Ventaja comparativa revelada
A7: Competidores regionales (Ecuador/Peru, taxo) | B7: 1.82 | C7: =(B7-1)/(B7+1) -> 0.29078014 | D7: 0.29 | E7: 0.15 | F7: =IF(B7>1,"Ventaja comparativa revelada","Desventaja comparativa") -> Ventaja comparativa revelada
A9: Contraste con datos primarios: en la subpartida 081090, Ecuador exporta cerca de tres veces lo de Colombia y Peru la supera ligeramente (ver hoja Andinos). Conviene revisar la lectura de 'baja escala exportadora' de los competidores regionales.

Sheet Matriz_Multicriterio
A1: Matriz multicriterio de priorizacion de mercados
A2: Puntajes de 1 a 5 por criterio. El total se calcula con SUMAPRODUCTO de puntajes por pesos.
A4: Criterio | B4: Peso | C4: Paises Bajos | D4: Alemania | E4: Espana | F4: Canada | G4: E.A.U.
A5: 1. Absorcion / volumen | B5: 0.3 | C5: 4.5 | D5: 5 | E5: 3.5 | F5: 3 | G5: 2.5
A6: 2. Logistica y cadena de frio | B6: 0.25 | C6: 5 | D6: 4.5 | E6: 4 | F6: 3.5 | G6: 3.5
A7: 3. Acceso fitosanitario | B7: 0.2 | C7: 4.5 | D7: 4 | E7: 4.5 | F7: 3 | G7: 3.5
A8: 4. Rol de hub | B8: 0.15 | C8: 5 | D8: 2 | E8: 3 | F8: 1.5 | G8: 4.5
A9: 5. Afinidad / precio | B9: 0.1 | C9: 3.5 | D9: 4 | E9: 5 | F9: 4 | G9: 4.5
A10: Suma de pesos (control) | B10: =SUM(B5:B9) -> 1
A11: Puntaje ponderado total | C11: =SUMPRODUCT($B$5:$B$9,C5:C9) -> 4.6 | D11: =SUMPRODUCT($B$5:$B$9,D5:D9) -> 4.125 | E11: =SUMPRODUCT($B$5:$B$9,E5:E9) -> 3.9 | F11: =SUMPRODUCT($B$5:$B$9,F5:F9) -> 3 | G11: =SUMPRODUCT($B$5:$B$9,G5:G9) -> 3.45
A12: Puntaje publicado en la ficha | C12: 4.55 | D12: 4.02 | E12: 3.85 | F12: 2.95 | G12: 3.47
A13: Ranking (sobre el recalculado) | C13: =RANK(C11,$C$11:$G$11,0) -> 1 | D13: =RANK(D11,$C$11:$G$11,0) -> 2 | E13: =RANK(E11,$C$11:$G$11,0) -> 3 | F13: =RANK(F11,$C$11:$G$11,0) -> 5 | G13: =RANK(G11,$C$11:$G$11,0) -> 4
A15: El recalculo mueve los puntajes hasta 0,10 puntos frente a los publicados, pero conserva intacto el orden de los cinco destinos: Paises Bajos, Alemania, Espana, E.A.U. y Canada.

Sheet Supuestos
A1: Registro de supuestos declarados
A2: Cada supuesto con su verificacion y su via de validacion.
A4: id | B4: supuesto | C4: valor | D4: justificacion_declarada | E4: verificacion_realizada | F4: estado | G4: como_validarlo
A5: S1 | B5: La curuba se estima como una fraccion fija del agregado comercial de la subpartida | C5: 3.8% | D5: La subpartida 0810.90 agrupa curuba con tamarindo, maracuya, litchi, pitahaya y otros frutos; no existe desagregacion oficial de curuba a seis digitos | E5: Verificado: el valor imputado del Conjunto C es exactamente 3.8% de la fila America Latina del Conjunto A en los seis anios (diferencia 0.0) | F5: Confirmado aritmeticamente | G5: Contrastar con el detalle transaccional de Legiscomex por partida y empresa exportadora
A6: S2 | B6: La participacion de la curuba en la produccion nacional de pasifloras | C6: 12.5% promedio | D6: Derivada de las series de produccion del Conjunto C (Agronet) | E6: Calculado: 12.55% (2019) a 12.47% (2024); no coincide con el factor comercial de 3.8% | F6: Magnitudes distintas documentadas | G6: Aclarar en el informe final que 3.8% es factor comercial y 12.5% es participacion productiva; no son intercambiables
A7: S3 | B7: El IBCR de Colombia se calcula sobre la subpartida 0810.90 agregada | C7: M=450 y X=2091.3 USD miles | D7: Base declarada en el tablero de posicion comercial de la ficha | E7: Verificado: IBCR = +0.646 coincide con el publicado | F7: Confirmado | G7: Recalcular con los datos definitivos de Trade Map por pais
A8: S4 | B8: El Grubel-Lloyd de la curuba se calcula sobre flujos especificos del producto | C8: GL=0.021 | D8: La curuba es un flujo unidireccional: Colombia exporta y practicamente no importa | E8: Base distinta a S3; se deriva M=22.19 USD miles para que GL y el IBCR de esa base reconcilien | F8: Base declarada por separado | G8: Obtener importaciones colombianas de curuba desagregadas en Legiscomex
A9: S5 | B9: Los pesos de la matriz multicriterio suman 100% | C9: 30/25/20/15/10 | D9: Ponderaciones asignadas por el equipo segun la logica IMSFEOG | E9: Verificado: suman exactamente 1.00 | F9: Confirmado | G9: Someter los pesos a analisis de sensibilidad (simulacion de +/- 15%)
A10: S6 | B10: El anio 2025 de Trade Map es utilizable para ranking mundial | C10: No | D10: Descarga de Trade Map con cobertura parcial del anio en curso | E10: Verificado: solo 109 de 160 economias reportan 2025 (68.1% de cobertura) | F10: Rechazado para ranking definitivo | G10: Usar 2024 (139 economias, 86.9%) como anio de referencia completo
A11: S7 | B11: El Coeficiente de Exportacion de la curuba | C11: 4.2% | D11: Declarado en la ficha tecnica como promedio estimado | E11: No recalculable con los campos disponibles: requiere el valor de la produccion nacional en USD, no el tonelaje | F11: Pendiente | G11: Obtener valor de produccion en DANE / EMIS / Agronet para cerrar la formula X/Produccion

Sheet Diccionario
A1: Diccionario de datos
A2: Definicion, unidad, fuente y periodo de cada campo del anexo.
A4: archivo | B4: campo | C4: tipo | D4: unidad | E4: definicion | F4: fuente | G4: periodo
A5: 03_datos_limpios/t1_exportadores_081090_ancho.csv | B5: codigo_tm | C5: texto | D5: - | E5: Codigo numerico de economia reportante (estilo UN Comtrade) | F5: Trade Map (ITC) | G5: 2016-2025
A6: 03_datos_limpios/t1_exportadores_081090_ancho.csv | B6: pais | C6: texto | D6: - | E6: Nombre de la economia exportadora | F6: Trade Map (ITC) | G6: 2016-2025
A7: 03_datos_limpios/t1_exportadores_081090_ancho.csv | B7: 2016..2025 | C7: numerico | D7: USD miles | E7: Valor exportado de la subpartida 081090 al mundo | F7: Trade Map (ITC) | G7: 2016-2025
A8: 03_datos_limpios/t2_exportadores_081090_largo.csv | B8: anio | C8: entero | D8: anio | E8: Anio de referencia del flujo | F8: Trade Map (ITC) | G8: 2016-2025
A9: 03_datos_limpios/t2_exportadores_081090_largo.csv | B9: exportaciones_usd_miles | C9: numerico | D9: USD miles | E9: Valor exportado (formato largo/tidy) | F9: Trade Map (ITC) | G9: 2016-2025
A10: 03_datos_limpios/t3_mundo_081090.csv | B10: exportaciones_mundiales_usd_miles | C10: numerico | D10: USD miles | E10: Fila Mundo del archivo crudo: total mundial exportado | F10: Trade Map (ITC) | G10: 2016-2025
A11: 03_datos_limpios/a1_comercio_mundial_equipo.csv | B11: region | C11: texto | D11: - | E11: Agrupacion regional usada por el equipo en el Conjunto A | F11: Elaboracion del equipo | G11: 2019-2024
A12: 03_datos_limpios/a1_comercio_mundial_equipo.csv | B12: 2019..2024 | C12: numerico | D12: USD miles | E12: Comercio mundial de pasifloras/frutas estimado por region | F12: Elaboracion del equipo | G12: 2019-2024
A13: 03_datos_limpios/a2_comercio_mundial_derivados.csv | B13: participacion_*_pct | C13: numerico | D13: % | E13: Participacion de cada region en el total del Conjunto A | F13: Calculado | G13: 2019-2024
A14: 03_datos_limpios/a2_comercio_mundial_derivados.csv | B14: cagr_2019_2024_pct | C14: numerico | D14: % | E14: Tasa de crecimiento anual compuesta del total | F14: Calculado | G14: 2019-2024
A15: 03_datos_limpios/b1_macro_colombia.csv | B15: variable | C15: texto | D15: - | E15: Variable macroeconomica de Colombia (PIB agricola / TRM / IPC) | F15: Banco Mundial WDI (declarado por el equipo) | G15: 2019-2024
... A37: 05_indicadores_equipo/i4_matriz_multicriterio.csv | B37: Puntaje ponderado total (recalculado) | C37: numerico | D37: puntaje 0-5 | E37: Suma producto de puntajes por pesos | F37: Calculado | G37: 2026
